Workbook

Sheet Instructions
A1: esm(R) | Workflow Data Collection Template
A2: Complete the tabs below so ESM Solutions can configure your approval workflows.
A4: OVERVIEW
A5: What is this? | B5: This template collects your institution's purchase order approval workflow rules. Once complete, return it to your ESM Solutions Consultant, who will use it to configure your system.
A6: Who fills this out? | B6: Your project team - typically the business office or finance lead who knows your approval hierarchy and department codes.
A8: HOW TO USE THIS TEMPLATE
A9: Step 1 - Gather your information | B9: Before filling out this template, collect: - Your Organization Codes (Segment 2 values) for each department - The email addresses of each approver (the same email used for system login) - Your approval dollar thresholds per level (for Steps 3-5) - Any special approval rules (grant funds, specific account codes, etc.)
A10: Step 2 - Go to each tab | B10: Work through the Step tabs (Step 1 through Step 15) in order. Not all steps may apply to your institution - skip or delete any that don't apply. Steps 7-15 are pre-built placeholders that your ESM Solutions Consultant will rename to match your approval hierarchy.
A11: Step 3 - Complete one row per rule | B11: Each row represents one approval rule. If the same approver handles multiple departments, you need one row per department.
A12: Step 4 - Return the file | B12: When complete, email the file back to your ESM Solutions Consultant.
A14: COLOR CODING GUIDE
A15: White cells * | B15: Required or optional data entry fields. Enter your data here.
A16: Gray cells (pre-filled) | B16: These fields are pre-configured by ESM. Do not modify them.
A17: Blue-tinted cells | B17: Reference only - enter approver names here for your own records. This information is NOT imported into the system.
A18: Amber rows | B18: These rows contain field-by-field instructions. Read them before filling in data below.
A20: UNDERSTANDING APPROVAL OPERATORS
A21: NEXT | B21: Approvers are notified sequentially. Approver 2 is only notified after Approver 1 approves.
A22: AND | B22: All approvers are notified simultaneously and all must approve before the order proceeds.
A23: OR | B23: All approvers are notified simultaneously but only one needs to approve for the order to proceed.
A25: TIPS & COMMON MISTAKES
A26: * marks required fields | B26: Columns marked with * must be filled in for every row. Rows missing required fields will fail to import.
A27: Workflow Name must be unique | B27: Every row must have a different Workflow Name. Using the same name on two rows will cause an error.
A28: Use email addresses, not names | B28: The system identifies approvers by email address. A name column is provided for your reference but is not imported.
A29: i Questions? Contact your ESM Solutions Consultant.

Sheet Step 1 - Budget Manager
A1: esm(R) | [Customer Name] - Step 1 - Budget Manager Approval
A2: Complete one row per approval rule. Fund Code, Organization Code, and/or Other Criteria define when this step is triggered. Each unique combination needs its own row.
A3: # | B3: Workflow Name * | C3: Fund Code | D3: Organization Code | E3: Other Criteria | F3: Priority | G3: Operator | H3: Approver 1 Email * | I3: Approver 1 Name | J3: Appr 1-2 Operator | K3: Approver 2 Email | L3: Approver 2 Name | M3: Appr 2-3 Operator | N3: Approver 3 Email | O3: Approver 3 Name | P3: Notes
A4: INSTRUCTIONS -> | B4: Unique name per row. Max 50 chars. Example: Budget Manager Approval - 011001 | C4: Segment 1 value in ESM system. Leave blank if not applicable. Example: 110000 | D4: Segment 2 value in ESM system. Leave blank if not applicable. Example: 011001 | E4: Any additional criteria not covered by Fund Code or Org Code. Example: Account Code, Auxiliary Field value, etc. | F4: Pre-filled: 100 Pre-set. Do not change. | G4: Pre-filled: AND Pre-set. Do not change. | H4: Required. Email address. Example: jane.doe@institution.edu | I4: Reference only - name is NOT imported. | J4: Required if Approver 2 added. NEXT = sequential | AND = all must approve | OR = any one approves | K4: Optional. Email address. | L4: Reference only - not imported. | M4: Required if Approver 3 added. | N4: Optional. Email address. | O4: Reference only - not imported. | P4: Any additional information.
A5: =IF(B5="","",ROW()-4) | F5: 100 | G5: AND
A6: =IF(B6="","",ROW()-4) | F6: 100 | G6: AND
A7: =IF(B7="","",ROW()-4) | F7: 100 | G7: AND
A8: =IF(B8="","",ROW()-4) | F8: 100 | G8: AND
A9: =IF(B9="","",ROW()-4) | F9: 100 | G9: AND
A10: =IF(B10="","",ROW()-4) | F10: 100 | G10: AND
A11: =IF(B11="","",ROW()-4) | F11: 100 | G11: AND
A12: =IF(B12="","",ROW()-4) | F12: 100 | G12: AND
A13: =IF(B13="","",ROW()-4) | F13: 100 | G13: AND
A14: =IF(B14="","",ROW()-4) | F14: 100 | G14: AND
A15: =IF(B15="","",ROW()-4) | F15: 100 | G15: AND
A16: =IF(B16="","",ROW()-4) | F16: 100 | G16: AND
... A54: =IF(B54="","",ROW()-4) | F54: 100 | G54: AND
A55: (C) 2026 ESM Solutions Corporation | Confidential

Sheet Step 2 - Special
A1: esm(R) | [Customer Name] - Step 2 - Special Approvals
A2: Complete one row per special approval rule. Use Fund Code, Organization Code, and/or Other Criteria (e.g. Account Code, Auxiliary Field) to define when this approval is triggered.
A3: # | B3: Workflow Name * | C3: Fund Code | D3: Organization Code | E3: Other Criteria | F3: Priority | G3: Operator | H3: Approver 1 Email * | I3: Approver 1 Name | J3: Appr 1-2 Operator | K3: Approver 2 Email | L3: Approver 2 Name | M3: Appr 2-3 Operator | N3: Notes
A4: INSTRUCTIONS -> | B4: Unique name per row. Max 50 chars. Example: Special Approval - Grant Fund | C4: Segment 1 value in ESM system. Leave blank if not applicable. Example: 110000 | D4: Segment 2 value in ESM system. Leave blank if not applicable. Example: 011001 | E4: Enter Account Code, Auxiliary Field, or other value that triggers this rule. Leave blank if not applicable. | F4: Pre-filled: 200 Pre-set. Do not change. | G4: Pre-filled: AND Pre-set. Do not change. | H4: Required. Email address. Example: jane.doe@institution.edu | I4: Reference only - name is NOT imported. | J4: Required if Approver 2 added. NEXT = sequential | AND = all must approve | OR = any one approves | K4: Optional. Email address. | L4: Reference only - not imported. | M4: Required if Approver 3 added. | N4: Any additional information.
A5: =IF(B5="","",ROW()-4) | F5: 200 | G5: AND
A6: =IF(B6="","",ROW()-4) | F6: 200 | G6: AND
A7: =IF(B7="","",ROW()-4) | F7: 200 | G7: AND
A8: =IF(B8="","",ROW()-4) | F8: 200 | G8: AND
A9: =IF(B9="","",ROW()-4) | F9: 200 | G9: AND
A10: =IF(B10="","",ROW()-4) | F10: 200 | G10: AND
A11: =IF(B11="","",ROW()-4) | F11: 200 | G11: AND
A12: =IF(B12="","",ROW()-4) | F12: 200 | G12: AND
A13: =IF(B13="","",ROW()-4) | F13: 200 | G13: AND
A14: =IF(B14="","",ROW()-4) | F14: 200 | G14: AND
A15: =IF(B15="","",ROW()-4) | F15: 200 | G15: AND
A16: =IF(B16="","",ROW()-4) | F16: 200 | G16: AND
... A54: =IF(B54="","",ROW()-4) | F54: 200 | G54: AND
A55: (C) 2026 ESM Solutions Corporation | Confidential

Sheet Step 3 - Dean-Director-AVP
A1: esm(R) | [Customer Name] - Step 3 - Dean / Director / AVP Approval
A2: Complete one row per approval rule. Fund Code, Organization Code, and/or Other Criteria define when this step is triggered. Transaction Total sets the minimum order amount.
A3: # | B3: Workflow Name * | C3: Fund Code | D3: Organization Code | E3: Other Criteria | F3: Transaction Total (Min $) | G3: Priority | H3: Operator | I3: Approver 1 Email * | J3: Approver 1 Name | K3: Appr 1-2 Operator | L3: Approver 2 Email | M3: Approver 2 Name | N3: Appr 2-3 Operator | O3: Notes
A4: INSTRUCTIONS -> | B4: Unique name per row. Max 50 chars. Example: Dean-Director-AVP Approval - 011001 | C4: Segment 1 value in ESM system. Leave blank if not applicable. Example: 110000 | D4: Segment 2 value in ESM system. Leave blank if not applicable. Example: 011001 | E4: Any additional criteria not covered by Fund Code or Org Code. Leave blank if not applicable. | F4: Minimum order amount that triggers this step. Example: 10000 | G4: Pre-filled: 300 Pre-set. Do not change. | H4: Pre-filled: AND Pre-set. Do not change. | I4: Required. Email address. | J4: Reference only - not imported. | K4: Required if Approver 2 added. NEXT = sequential | AND = all must approve | OR = any one approves | L4: Optional. | M4: Reference only - not imported. | N4: Required if Approver 3 added. | O4: Any additional information.
A5: =IF(B5="","",ROW()-4) | G5: 300 | H5: AND
A6: =IF(B6="","",ROW()-4) | G6: 300 | H6: AND
A7: =IF(B7="","",ROW()-4) | G7: 300 | H7: AND
A8: =IF(B8="","",ROW()-4) | G8: 300 | H8: AND
A9: =IF(B9="","",ROW()-4) | G9: 300 | H9: AND
A10: =IF(B10="","",ROW()-4) | G10: 300 | H10: AND
A11: =IF(B11="","",ROW()-4) | G11: 300 | H11: AND
A12: =IF(B12="","",ROW()-4) | G12: 300 | H12: AND
A13: =IF(B13="","",ROW()-4) | G13: 300 | H13: AND
A14: =IF(B14="","",ROW()-4) | G14: 300 | H14: AND
A15: =IF(B15="","",ROW()-4) | G15: 300 | H15: AND
A16: =IF(B16="","",ROW()-4) | G16: 300 | H16: AND
... A54: =IF(B54="","",ROW()-4) | G54: 300 | H54: AND
A55: (C) 2026 ESM Solutions Corporation | Confidential

Sheet Step 4 - Vice President
A1: esm(R) | [Customer Name] - Step 4 - Vice President Approval
A2: Complete one row per approval rule. Fund Code, Organization Code, and/or Other Criteria define when this step is triggered. Transaction Total sets the minimum order amount.
A3: # | B3: Workflow Name * | C3: Fund Code | D3: Organization Code | E3: Other Criteria | F3: Transaction Total (Min $) | G3: Priority | H3: Operator | I3: Approver 1 Email * | J3: Approver 1 Name | K3: Appr 1-2 Operator | L3: Approver 2 Email | M3: Approver 2 Name | N3: Appr 2-3 Operator | O3: Notes
A4: INSTRUCTIONS -> | B4: Unique name per row. Max 50 chars. Example: Vice President Approval - 011001 | C4: Segment 1 value in ESM system. Leave blank if not applicable. Example: 110000 | D4: Segment 2 value in ESM system. Leave blank if not applicable. Example: 011001 | E4: Any additional criteria not covered by Fund Code or Org Code. Leave blank if not applicable. | F4: Minimum order amount that triggers this step. Example: 25000 | G4: Pre-filled: 400 Pre-set. Do not change. | H4: Pre-filled: AND Pre-set. Do not change. | I4: Required. Email address. | J4: Reference only - not imported. | K4: Required if Approver 2 added. | L4: Optional. | M4: Reference only - not imported. | N4: Required if Approver 3 added. | O4: Any additional information.
A5: =IF(B5="","",ROW()-4) | G5: 400 | H5: AND
A6: =IF(B6="","",ROW()-4) | G6: 400 | H6: AND
A7: =IF(B7="","",ROW()-4) | G7: 400 | H7: AND
A8: =IF(B8="","",ROW()-4) | G8: 400 | H8: AND
A9: =IF(B9="","",ROW()-4) | G9: 400 | H9: AND
A10: =IF(B10="","",ROW()-4) | G10: 400 | H10: AND
A11: =IF(B11="","",ROW()-4) | G11: 400 | H11: AND
A12: =IF(B12="","",ROW()-4) | G12: 400 | H12: AND
A13: =IF(B13="","",ROW()-4) | G13: 400 | H13: AND
A14: =IF(B14="","",ROW()-4) | G14: 400 | H14: AND
A15: =IF(B15="","",ROW()-4) | G15: 400 | H15: AND
A16: =IF(B16="","",ROW()-4) | G16: 400 | H16: AND
... A54: =IF(B54="","",ROW()-4) | G54: 400 | H54: AND
A55: (C) 2026 ESM Solutions Corporation | Confidential

Sheet Step 5 - President
A1: esm(R) | [Customer Name] - Step 5 - President Approval
A2: Complete one row per approval rule. Fund Code, Organization Code, and/or Other Criteria define when this step is triggered. Transaction Total sets the minimum order amount.
A3: # | B3: Workflow Name * | C3: Fund Code | D3: Organization Code | E3: Other Criteria | F3: Transaction Total (Min $) | G3: Priority | H3: Operator | I3: Approver 1 Email * | J3: Approver 1 Name | K3: Appr 1-2 Operator | L3: Approver 2 Email | M3: Approver 2 Name | N3: Appr 2-3 Operator | O3: Notes
A4: INSTRUCTIONS -> | B4: Unique name per row. Max 50 chars. Example: President Approval - 011001 | C4: Segment 1 value in ESM system. Leave blank if not applicable. Example: 110000 | D4: Segment 2 value in ESM system. Leave blank if not applicable. Example: 011001 | E4: Any additional criteria not covered by Fund Code or Org Code. Leave blank if not applicable. | F4: Minimum order amount that triggers this step. Example: 100000 | G4: Pre-filled: 500 Pre-set. Do not change. | H4: Pre-filled: AND Pre-set. Do not change. | I4: Required. Email address. | J4: Reference only - not imported. | K4: Required if Approver 2 added. | L4: Optional. | M4: Reference only - not imported. | N4: Required if Approver 3 added. | O4: Any additional information.
A5: =IF(B5="","",ROW()-4) | G5: 500 | H5: AND
A6: =IF(B6="","",ROW()-4) | G6: 500 | H6: AND
A7: =IF(B7="","",ROW()-4) | G7: 500 | H7: AND
A8: =IF(B8="","",ROW()-4) | G8: 500 | H8: AND
A9: =IF(B9="","",ROW()-4) | G9: 500 | H9: AND
A10: =IF(B10="","",ROW()-4) | G10: 500 | H10: AND
A11: =IF(B11="","",ROW()-4) | G11: 500 | H11: AND
A12: =IF(B12="","",ROW()-4) | G12: 500 | H12: AND
A13: =IF(B13="","",ROW()-4) | G13: 500 | H13: AND
A14: =IF(B14="","",ROW()-4) | G14: 500 | H14: AND
A15: =IF(B15="","",ROW()-4) | G15: 500 | H15: AND
A16: =IF(B16="","",ROW()-4) | G16: 500 | H16: AND
... A54: =IF(B54="","",ROW()-4) | G54: 500 | H54: AND
A55: (C) 2026 ESM Solutions Corporation | Confidential

Sheet Step 6 - Purchasing
A1: esm(R) | [Customer Name] - Step 6 - Purchasing Approval
A2: Complete one row per Purchasing approval rule. Fund Code, Organization Code, and/or Other Criteria define when Purchasing review is required.
A3: # | B3: Workflow Name * | C3: Fund Code | D3: Organization Code | E3: Other Criteria | F3: Priority | G3: Operator | H3: Approver 1 Email * | I3: Approver 1 Name | J3: Appr 1-2 Operator | K3: Approver 2 Email | L3: Approver 2 Name | M3: Appr 2-3 Operator | N3: Notes
A4: INSTRUCTIONS -> | B4: Unique name per row. Max 50 chars. Example: Purchasing Approval - EH&S | C4: Segment 1 value in ESM system. Leave blank if not applicable. Example: 110000 | D4: Segment 2 value in ESM system. Leave blank if not applicable. Example: 011001 | E4: Any additional criteria not covered by Fund Code or Org Code. Leave blank if not applicable. | F4: Pre-filled: 600 Pre-set. Do not change. | G4: Pre-filled: AND Pre-set. Do not change. | H4: Required. Email address. | I4: Reference only - not imported. | J4: Required if Approver 2 added. | K4: Optional. | L4: Reference only - not imported. | M4: Required if Approver 3 added. | N4: Any additional information.
A5: =IF(B5="","",ROW()-4) | F5: 600 | G5: AND
A6: =IF(B6="","",ROW()-4) | F6: 600 | G6: AND
A7: =IF(B7="","",ROW()-4) | F7: 600 | G7: AND
A8: =IF(B8="","",ROW()-4) | F8: 600 | G8: AND
A9: =IF(B9="","",ROW()-4) | F9: 600 | G9: AND
A10: =IF(B10="","",ROW()-4) | F10: 600 | G10: AND
A11: =IF(B11="","",ROW()-4) | F11: 600 | G11: AND
A12: =IF(B12="","",ROW()-4) | F12: 600 | G12: AND
A13: =IF(B13="","",ROW()-4) | F13: 600 | G13: AND
A14: =IF(B14="","",ROW()-4) | F14: 600 | G14: AND
A15: =IF(B15="","",ROW()-4) | F15: 600 | G15: AND
A16: =IF(B16="","",ROW()-4) | F16: 600 | G16: AND
... A54: =IF(B54="","",ROW()-4) | F54: 600 | G54: AND
A55: (C) 2026 ESM Solutions Corporation | Confidential

Sheet Step 7 - Dept Head
A1: esm(R) | [Customer Name] - Step 7 - Department Head Approval
A2: Placeholder step 7. Rename this tab and update the title to match your institution's approval hierarchy. Delete this tab if not needed.
A3: # | B3: Workflow Name * | C3: Fund Code | D3: Organization Code | E3: Other Criteria | F3: Transaction Total (Min $) | G3: Priority | H3: Operator | I3: Approver 1 Email * | J3: Approver 1 Name | K3: Appr 1-2 Operator | L3: Approver 2 Email | M3: Approver 2 Name | N3: Appr 2-3 Operator | O3: Notes
A4: INSTRUCTIONS -> | B4: Unique name per row. Max 50 chars. Example: Department Head Approval - 011001 | C4: Segment 1 value in ESM system. Leave blank if not applicable. Example: 110000 | D4: Segment 2 value in ESM system. Leave blank if not applicable. Example: 011001 | E4: Any additional criteria not covered by Fund Code or Org Code. Leave blank if not applicable. | F4: Minimum order amount that triggers this step. Leave blank if no dollar threshold applies. | G4: Pre-filled: 700 Pre-set. Do not change. | H4: Pre-filled: AND Pre-set. Do not change. | I4: Required. Email address. | J4: Reference only - not imported. | K4: Required if Approver 2 added. NEXT = sequential | AND = all must approve | OR = any one approves | L4: Optional. | M4: Reference only - not imported. | N4: Required if Approver 3 added. | O4: Any additional information.
A5: =IF(B5="","",ROW()-4) | G5: 700 | H5: AND
A6: =IF(B6="","",ROW()-4) | G6: 700 | H6: AND
A7: =IF(B7="","",ROW()-4) | G7: 700 | H7: AND
A8: =IF(B8="","",ROW()-4) | G8: 700 | H8: AND
A9: =IF(B9="","",ROW()-4) | G9: 700 | H9: AND
A10: =IF(B10="","",ROW()-4) | G10: 700 | H10: AND
A11: =IF(B11="","",ROW()-4) | G11: 700 | H11: AND
A12: =IF(B12="","",ROW()-4) | G12: 700 | H12: AND
A13: =IF(B13="","",ROW()-4) | G13: 700 | H13: AND
A14: =IF(B14="","",ROW()-4) | G14: 700 | H14: AND
A15: =IF(B15="","",ROW()-4) | G15: 700 | H15: AND
A16: =IF(B16="","",ROW()-4) | G16: 700 | H16: AND
... A54: =IF(B54="","",ROW()-4) | G54: 700 | H54: AND
A55: (C) 2026 ESM Solutions Corporation | Confidential

Sheet Step 8 - Controller
A1: esm(R) | [Customer Name] - Step 8 - Controller Approval
A2: Placeholder step 8. Rename this tab and update the title to match your institution's approval hierarchy. Delete this tab if not needed.
A3: # | B3: Workflow Name * | C3: Fund Code | D3: Organization Code | E3: Other Criteria | F3: Transaction Total (Min $) | G3: Priority | H3: Operator | I3: Approver 1 Email * | J3: Approver 1 Name | K3: Appr 1-2 Operator | L3: Approver 2 Email | M3: Approver 2 Name | N3: Appr 2-3 Operator | O3: Notes
A4: INSTRUCTIONS -> | B4: Unique name per row. Max 50 chars. Example: Controller Approval - 011001 | C4: Segment 1 value in ESM system. Leave blank if not applicable. Example: 110000 | D4: Segment 2 value in ESM system. Leave blank if not applicable. Example: 011001 | E4: Any additional criteria not covered by Fund Code or Org Code. Leave blank if not applicable. | F4: Minimum order amount that triggers this step. Leave blank if no dollar threshold applies. | G4: Pre-filled: 800 Pre-set. Do not change. | H4: Pre-filled: AND Pre-set. Do not change. | I4: Required. Email address. | J4: Reference only - not imported. | K4: Required if Approver 2 added. NEXT = sequential | AND = all must approve | OR = any one approves | L4: Optional. | M4: Reference only - not imported. | N4: Required if Approver 3 added. | O4: Any additional information.
A5: =IF(B5="","",ROW()-4) | G5: 800 | H5: AND
A6: =IF(B6="","",ROW()-4) | G6: 800 | H6: AND
A7: =IF(B7="","",ROW()-4) | G7: 800 | H7: AND
A8: =IF(B8="","",ROW()-4) | G8: 800 | H8: AND
A9: =IF(B9="","",ROW()-4) | G9: 800 | H9: AND
A10: =IF(B10="","",ROW()-4) | G10: 800 | H10: AND
A11: =IF(B11="","",ROW()-4) | G11: 800 | H11: AND
A12: =IF(B12="","",ROW()-4) | G12: 800 | H12: AND
A13: =IF(B13="","",ROW()-4) | G13: 800 | H13: AND
A14: =IF(B14="","",ROW()-4) | G14: 800 | H14: AND
A15: =IF(B15="","",ROW()-4) | G15: 800 | H15: AND
A16: =IF(B16="","",ROW()-4) | G16: 800 | H16: AND
... A54: =IF(B54="","",ROW()-4) | G54: 800 | H54: AND
A55: (C) 2026 ESM Solutions Corporation | Confidential

Sheet Step 9 - CFO
A1: esm(R) | [Customer Name] - Step 9 - CFO Approval
A2: Placeholder step 9. Rename this tab and update the title to match your institution's approval hierarchy. Delete this tab if not needed.
A3: # | B3: Workflow Name * | C3: Fund Code | D3: Organization Code | E3: Other Criteria | F3: Transaction Total (Min $) | G3: Priority | H3: Operator | I3: Approver 1 Email * | J3: Approver 1 Name | K3: Appr 1-2 Operator | L3: Approver 2 Email | M3: Approver 2 Name | N3: Appr 2-3 Operator | O3: Notes
A4: INSTRUCTIONS -> | B4: Unique name per row. Max 50 chars. Example: CFO Approval - 011001 | C4: Segment 1 value in ESM system. Leave blank if not applicable. Example: 110000 | D4: Segment 2 value in ESM system. Leave blank if not applicable. Example: 011001 | E4: Any additional criteria not covered by Fund Code or Org Code. Leave blank if not applicable. | F4: Minimum order amount that triggers this step. Leave blank if no dollar threshold applies. | G4: Pre-filled: 900 Pre-set. Do not change. | H4: Pre-filled: AND Pre-set. Do not change. | I4: Required. Email address. | J4: Reference only - not imported. | K4: Required if Approver 2 added. NEXT = sequential | AND = all must approve | OR = any one approves | L4: Optional. | M4: Reference only - not imported. | N4: Required if Approver 3 added. | O4: Any additional information.
A5: =IF(B5="","",ROW()-4) | G5: 900 | H5: AND
A6: =IF(B6="","",ROW()-4) | G6: 900 | H6: AND
A7: =IF(B7="","",ROW()-4) | G7: 900 | H7: AND
A8: =IF(B8="","",ROW()-4) | G8: 900 | H8: AND
A9: =IF(B9="","",ROW()-4) | G9: 900 | H9: AND
A10: =IF(B10="","",ROW()-4) | G10: 900 | H10: AND
A11: =IF(B11="","",ROW()-4) | G11: 900 | H11: AND
A12: =IF(B12="","",ROW()-4) | G12: 900 | H12: AND
A13: =IF(B13="","",ROW()-4) | G13: 900 | H13: AND
A14: =IF(B14="","",ROW()-4) | G14: 900 | H14: AND
A15: =IF(B15="","",ROW()-4) | G15: 900 | H15: AND
A16: =IF(B16="","",ROW()-4) | G16: 900 | H16: AND
... A54: =IF(B54="","",ROW()-4) | G54: 900 | H54: AND
A55: (C) 2026 ESM Solutions Corporation | Confidential

Sheet Step 10 - Provost
A1: esm(R) | [Customer Name] - Step 10 - Provost Approval
A2: Placeholder step 10. Rename this tab and update the title to match your institution's approval hierarchy. Delete this tab if not needed.
A3: # | B3: Workflow Name * | C3: Fund Code | D3: Organization Code | E3: Other Criteria | F3: Transaction Total (Min $) | G3: Priority | H3: Operator | I3: Approver 1 Email * | J3: Approver 1 Name | K3: Appr 1-2 Operator | L3: Approver 2 Email | M3: Approver 2 Name | N3: Appr 2-3 Operator | O3: Notes
A4: INSTRUCTIONS -> | B4: Unique name per row. Max 50 chars. Example: Provost Approval - 011001 | C4: Segment 1 value in ESM system. Leave blank if not applicable. Example: 110000 | D4: Segment 2 value in ESM system. Leave blank if not applicable. Example: 011001 | E4: Any additional criteria not covered by Fund Code or Org Code. Leave blank if not applicable. | F4: Minimum order amount that triggers this step. Leave blank if no dollar threshold applies. | G4: Pre-filled: 1000 Pre-set. Do not change. | H4: Pre-filled: AND Pre-set. Do not change. | I4: Required. Email address. | J4: Reference only - not imported. | K4: Required if Approver 2 added. NEXT = sequential | AND = all must approve | OR = any one approves | L4: Optional. | M4: Reference only - not imported. | N4: Required if Approver 3 added. | O4: Any additional information.
A5: =IF(B5="","",ROW()-4) | G5: 1000 | H5: AND
A6: =IF(B6="","",ROW()-4) | G6: 1000 | H6: AND
A7: =IF(B7="","",ROW()-4) | G7: 1000 | H7: AND
A8: =IF(B8="","",ROW()-4) | G8: 1000 | H8: AND
A9: =IF(B9="","",ROW()-4) | G9: 1000 | H9: AND
A10: =IF(B10="","",ROW()-4) | G10: 1000 | H10: AND
A11: =IF(B11="","",ROW()-4) | G11: 1000 | H11: AND
A12: =IF(B12="","",ROW()-4) | G12: 1000 | H12: AND
A13: =IF(B13="","",ROW()-4) | G13: 1000 | H13: AND
A14: =IF(B14="","",ROW()-4) | G14: 1000 | H14: AND
A15: =IF(B15="","",ROW()-4) | G15: 1000 | H15: AND
A16: =IF(B16="","",ROW()-4) | G16: 1000 | H16: AND
... A54: =IF(B54="","",ROW()-4) | G54: 1000 | H54: AND
A55: (C) 2026 ESM Solutions Corporation | Confidential

Sheet Step 11 - Board
A1: esm(R) | [Customer Name] - Step 11 - Board / Trustee Approval
A2: Placeholder step 11. Rename this tab and update the title to match your institution's approval hierarchy. Delete this tab if not needed.
A3: # | B3: Workflow Name * | C3: Fund Code | D3: Organization Code | E3: Other Criteria | F3: Transaction Total (Min $) | G3: Priority | H3: Operator | I3: Approver 1 Email * | J3: Approver 1 Name | K3: Appr 1-2 Operator | L3: Approver 2 Email | M3: Approver 2 Name | N3: Appr 2-3 Operator | O3: Notes
A4: INSTRUCTIONS -> | B4: Unique name per row. Max 50 chars. Example: Board / Trustee Approval - 011001 | C4: Segment 1 value in ESM system. Leave blank if not applicable. Example: 110000 | D4: Segment 2 value in ESM system. Leave blank if not applicable. Example: 011001 | E4: Any additional criteria not covered by Fund Code or Org Code. Leave blank if not applicable. | F4: Minimum order amount that triggers this step. Leave blank if no dollar threshold applies. | G4: Pre-filled: 1100 Pre-set. Do not change. | H4: Pre-filled: AND Pre-set. Do not change. | I4: Required. Email address. | J4: Reference only - not imported. | K4: Required if Approver 2 added. NEXT = sequential | AND = all must approve | OR = any one approves | L4: Optional. | M4: Reference only - not imported. | N4: Required if Approver 3 added. | O4: Any additional information.
A5: =IF(B5="","",ROW()-4) | G5: 1100 | H5: AND
A6: =IF(B6="","",ROW()-4) | G6: 1100 | H6: AND
A7: =IF(B7="","",ROW()-4) | G7: 1100 | H7: AND
A8: =IF(B8="","",ROW()-4) | G8: 1100 | H8: AND
A9: =IF(B9="","",ROW()-4) | G9: 1100 | H9: AND
A10: =IF(B10="","",ROW()-4) | G10: 1100 | H10: AND
A11: =IF(B11="","",ROW()-4) | G11: 1100 | H11: AND
A12: =IF(B12="","",ROW()-4) | G12: 1100 | H12: AND
A13: =IF(B13="","",ROW()-4) | G13: 1100 | H13: AND
A14: =IF(B14="","",ROW()-4) | G14: 1100 | H14: AND
A15: =IF(B15="","",ROW()-4) | G15: 1100 | H15: AND
A16: =IF(B16="","",ROW()-4) | G16: 1100 | H16: AND
... A54: =IF(B54="","",ROW()-4) | G54: 1100 | H54: AND
A55: (C) 2026 ESM Solutions Corporation | Confidential

Sheet Step 12 - Legal
A1: esm(R) | [Customer Name] - Step 12 - Legal Review
A2: Placeholder step 12. Rename this tab and update the title to match your institution's approval hierarchy. Delete this tab if not needed.
A3: # | B3: Workflow Name * | C3: Fund Code | D3: Organization Code | E3: Other Criteria | F3: Transaction Total (Min $) | G3: Priority | H3: Operator | I3: Approver 1 Email * | J3: Approver 1 Name | K3: Appr 1-2 Operator | L3: Approver 2 Email | M3: Approver 2 Name | N3: Appr 2-3 Operator | O3: Notes
A4: INSTRUCTIONS -> | B4: Unique name per row. Max 50 chars. Example: Legal Review - 011001 | C4: Segment 1 value in ESM system. Leave blank if not applicable. Example: 110000 | D4: Segment 2 value in ESM system. Leave blank if not applicable. Example: 011001 | E4: Any additional criteria not covered by Fund Code or Org Code. Leave blank if not applicable. | F4: Minimum order amount that triggers this step. Leave blank if no dollar threshold applies. | G4: Pre-filled: 1200 Pre-set. Do not change. | H4: Pre-filled: AND Pre-set. Do not change. | I4: Required. Email address. | J4: Reference only - not imported. | K4: Required if Approver 2 added. NEXT = sequential | AND = all must approve | OR = any one approves | L4: Optional. | M4: Reference only - not imported. | N4: Required if Approver 3 added. | O4: Any additional information.
A5: =IF(B5="","",ROW()-4) | G5: 1200 | H5: AND
A6: =IF(B6="","",ROW()-4) | G6: 1200 | H6: AND
A7: =IF(B7="","",ROW()-4) | G7: 1200 | H7: AND
A8: =IF(B8="","",ROW()-4) | G8: 1200 | H8: AND
A9: =IF(B9="","",ROW()-4) | G9: 1200 | H9: AND
A10: =IF(B10="","",ROW()-4) | G10: 1200 | H10: AND
A11: =IF(B11="","",ROW()-4) | G11: 1200 | H11: AND
A12: =IF(B12="","",ROW()-4) | G12: 1200 | H12: AND
A13: =IF(B13="","",ROW()-4) | G13: 1200 | H13: AND
A14: =IF(B14="","",ROW()-4) | G14: 1200 | H14: AND
A15: =IF(B15="","",ROW()-4) | G15: 1200 | H15: AND
A16: =IF(B16="","",ROW()-4) | G16: 1200 | H16: AND
... A54: =IF(B54="","",ROW()-4) | G54: 1200 | H54: AND
A55: (C) 2026 ESM Solutions Corporation | Confidential

Sheet Step 13 - Compliance
A1: esm(R) | [Customer Name] - Step 13 - Compliance Review
A2: Placeholder step 13. Rename this tab and update the title to match your institution's approval hierarchy. Delete this tab if not needed.
A3: # | B3: Workflow Name * | C3: Fund Code | D3: Organization Code | E3: Other Criteria | F3: Transaction Total (Min $) | G3: Priority | H3: Operator | I3: Approver 1 Email * | J3: Approver 1 Name | K3: Appr 1-2 Operator | L3: Approver 2 Email | M3: Approver 2 Name | N3: Appr 2-3 Operator | O3: Notes
A4: INSTRUCTIONS -> | B4: Unique name per row. Max 50 chars. Example: Compliance Review - 011001 | C4: Segment 1 value in ESM system. Leave blank if not applicable. Example: 110000 | D4: Segment 2 value in ESM system. Leave blank if not applicable. Example: 011001 | E4: Any additional criteria not covered by Fund Code or Org Code. Leave blank if not applicable. | F4: Minimum order amount that triggers this step. Leave blank if no dollar threshold applies. | G4: Pre-filled: 1300 Pre-set. Do not change. | H4: Pre-filled: AND Pre-set. Do not change. | I4: Required. Email address. | J4: Reference only - not imported. | K4: Required if Approver 2 added. NEXT = sequential | AND = all must approve | OR = any one approves | L4: Optional. | M4: Reference only - not imported. | N4: Required if Approver 3 added. | O4: Any additional information.
A5: =IF(B5="","",ROW()-4) | G5: 1300 | H5: AND
A6: =IF(B6="","",ROW()-4) | G6: 1300 | H6: AND
A7: =IF(B7="","",ROW()-4) | G7: 1300 | H7: AND
A8: =IF(B8="","",ROW()-4) | G8: 1300 | H8: AND
A9: =IF(B9="","",ROW()-4) | G9: 1300 | H9: AND
A10: =IF(B10="","",ROW()-4) | G10: 1300 | H10: AND
A11: =IF(B11="","",ROW()-4) | G11: 1300 | H11: AND
A12: =IF(B12="","",ROW()-4) | G12: 1300 | H12: AND
A13: =IF(B13="","",ROW()-4) | G13: 1300 | H13: AND
A14: =IF(B14="","",ROW()-4) | G14: 1300 | H14: AND
A15: =IF(B15="","",ROW()-4) | G15: 1300 | H15: AND
A16: =IF(B16="","",ROW()-4) | G16: 1300 | H16: AND
... A54: =IF(B54="","",ROW()-4) | G54: 1300 | H54: AND
A55: (C) 2026 ESM Solutions Corporation | Confidential

Sheet Step 14 - IT Review
A1: esm(R) | [Customer Name] - Step 14 - IT / Security Review
A2: Placeholder step 14. Rename this tab and update the title to match your institution's approval hierarchy. Delete this tab if not needed.
A3: # | B3: Workflow Name * | C3: Fund Code | D3: Organization Code | E3: Other Criteria | F3: Transaction Total (Min $) | G3: Priority | H3: Operator | I3: Approver 1 Email * | J3: Approver 1 Name | K3: Appr 1-2 Operator | L3: Approver 2 Email | M3: Approver 2 Name | N3: Appr 2-3 Operator | O3: Notes
A4: INSTRUCTIONS -> | B4: Unique name per row. Max 50 chars. Example: IT / Security Review - 011001 | C4: Segment 1 value in ESM system. Leave blank if not applicable. Example: 110000 | D4: Segment 2 value in ESM system. Leave blank if not applicable. Example: 011001 | E4: Any additional criteria not covered by Fund Code or Org Code. Leave blank if not applicable. | F4: Minimum order amount that triggers this step. Leave blank if no dollar threshold applies. | G4: Pre-filled: 1400 Pre-set. Do not change. | H4: Pre-filled: AND Pre-set. Do not change. | I4: Required. Email address. | J4: Reference only - not imported. | K4: Required if Approver 2 added. NEXT = sequential | AND = all must approve | OR = any one approves | L4: Optional. | M4: Reference only - not imported. | N4: Required if Approver 3 added. | O4: Any additional information.
A5: =IF(B5="","",ROW()-4) | G5: 1400 | H5: AND
A6: =IF(B6="","",ROW()-4) | G6: 1400 | H6: AND
A7: =IF(B7="","",ROW()-4) | G7: 1400 | H7: AND
A8: =IF(B8="","",ROW()-4) | G8: 1400 | H8: AND
A9: =IF(B9="","",ROW()-4) | G9: 1400 | H9: AND
A10: =IF(B10="","",ROW()-4) | G10: 1400 | H10: AND
A11: =IF(B11="","",ROW()-4) | G11: 1400 | H11: AND
A12: =IF(B12="","",ROW()-4) | G12: 1400 | H12: AND
A13: =IF(B13="","",ROW()-4) | G13: 1400 | H13: AND
A14: =IF(B14="","",ROW()-4) | G14: 1400 | H14: AND
A15: =IF(B15="","",ROW()-4) | G15: 1400 | H15: AND
A16: =IF(B16="","",ROW()-4) | G16: 1400 | H16: AND
... A54: =IF(B54="","",ROW()-4) | G54: 1400 | H54: AND
A55: (C) 2026 ESM Solutions Corporation | Confidential

Sheet Step 15 - Final Approval
A1: esm(R) | [Customer Name] - Step 15 - Final Approval
A2: Placeholder step 15. Rename this tab and update the title to match your institution's approval hierarchy. Delete this tab if not needed.
A3: # | B3: Workflow Name * | C3: Fund Code | D3: Organization Code | E3: Other Criteria | F3: Transaction Total (Min $) | G3: Priority | H3: Operator | I3: Approver 1 Email * | J3: Approver 1 Name | K3: Appr 1-2 Operator | L3: Approver 2 Email | M3: Approver 2 Name | N3: Appr 2-3 Operator | O3: Notes
A4: INSTRUCTIONS -> | B4: Unique name per row. Max 50 chars. Example: Final Approval - 011001 | C4: Segment 1 value in ESM system. Leave blank if not applicable. Example: 110000 | D4: Segment 2 value in ESM system. Leave blank if not applicable. Example: 011001 | E4: Any additional criteria not covered by Fund Code or Org Code. Leave blank if not applicable. | F4: Minimum order amount that triggers this step. Leave blank if no dollar threshold applies. | G4: Pre-filled: 1500 Pre-set. Do not change. | H4: Pre-filled: AND Pre-set. Do not change. | I4: Required. Email address. | J4: Reference only - not imported. | K4: Required if Approver 2 added. NEXT = sequential | AND = all must approve | OR = any one approves | L4: Optional. | M4: Reference only - not imported. | N4: Required if Approver 3 added. | O4: Any additional information.
A5: =IF(B5="","",ROW()-4) | G5: 1500 | H5: AND
A6: =IF(B6="","",ROW()-4) | G6: 1500 | H6: AND
A7: =IF(B7="","",ROW()-4) | G7: 1500 | H7: AND
A8: =IF(B8="","",ROW()-4) | G8: 1500 | H8: AND
A9: =IF(B9="","",ROW()-4) | G9: 1500 | H9: AND
A10: =IF(B10="","",ROW()-4) | G10: 1500 | H10: AND
A11: =IF(B11="","",ROW()-4) | G11: 1500 | H11: AND
A12: =IF(B12="","",ROW()-4) | G12: 1500 | H12: AND
A13: =IF(B13="","",ROW()-4) | G13: 1500 | H13: AND
A14: =IF(B14="","",ROW()-4) | G14: 1500 | H14: AND
A15: =IF(B15="","",ROW()-4) | G15: 1500 | H15: AND
A16: =IF(B16="","",ROW()-4) | G16: 1500 | H16: AND
... A54: =IF(B54="","",ROW()-4) | G54: 1500 | H54: AND
A55: (C) 2026 ESM Solutions Corporation | Confidential

Sheet ESM Import (SC Use)
A1: esm(R) | Workflow & Notification Import File - FOR SOLUTIONS CONSULTANT USE ONLY
A2: This tab auto-populates from the customer Step tabs. Once the customer returns the completed file: 1. Review data in rows below for accuracy. 2. Filter out any blank rows (column B = empty). 3. Copy rows 5 onward + save as CSV to create the import file.
A3: Template Version | B3: 1.1
A4: Workflow/Notification
A5: Status | B5: * Workflow Name | C5: * Order Notification Name | D5: Workflow Priority | E5: * Operator | F5: * Criteria 1 Name | G5: * Criteria 1 Condition | H5: * Criteria 1 Value | I5: Criteria 2 Name | J5: Criteria 2 Condition | K5: Criteria 2 Value | L5: Criteria 3 Name | M5: Criteria 3 Condition | N5: Criteria 3 Value | O5: Criteria 4 Name | P5: Criteria 4 Condition | Q5: Criteria 4 Value | R5: Criteria 5 Name | S5: Criteria 5 Condition | T5: Criteria 5 Value | U5: * Approver or Notified User 1 | V5: Approver 1 Operator | W5: Approver or Notified User 2 | X5: Approver 2 Operator | Y5: Approver or Notified User 3 | Z5: Approver 3 Operator | AA5: Approver or Notified User 4 | AB5: Approver 4 Operator | AC5: Approver or Notified User 5 | AD5: Approver 5 Operator | AE5: Approver or Notified User 6 | AF5: Approver 6 Operator | AG5: Approver or Notified User 7 | AH5: Approver 7 Operator | AI5: Approver or Notified User 8 | AJ5: Approver 8 Operator | AK5: Approver or Notified User 9 | AL5: Approver 9 Operator | AM5: Approver or Notified User 10
A6: Char = 8 | B6: Char = 50 | C6: Char = 50 | D6: Char = 5 | E6: Char = 3 | F6: Char = 100 | G6: Char = 16 | H6: Char = 100 | I6: Char = 100 | J6: Char = 16 | K6: Char = 100 | L6: Char = 100 | M6: Char = 16 | N6: Char = 100 | O6: Char = 100 | P6: Char = 16 | Q6: Char = 100 | R6: Char = 100 | S6: Char = 16 | T6: Char = 100 | U6: Char = 100 | V6: Char = 4 | W6: Char = 100 | X6: Char = 4 | Y6: Char = 100 | Z6: Char = 4 | AA6: Char = 100 | AB6: Char = 4 | AC6: Char = 100 | AD6: Char = 4 | AE6: Char = 100 | AF6: Char = 4 | AG6: Char = 100 | AH6: Char = 4 | AI6: Char = 100 | AJ6: Char = 4 | AK6: Char = 100 | AL6: Char = 4 | AM6: Char = 100
A7: v Step 1 - Budget Manager Approval (from 'Step 1 - Budget Manager' tab) v
A8: =IF('Step 1 - Budget Manager'!B5="","","Active") | B8: =IF('Step 1 - Budget Manager'!B5="","",'Step 1 - Budget Manager'!B5) | C8: =IF('Step 1 - Budget Manager'!B5="","",'Step 1 - Budget Manager'!B5) | D8: =IF('Step 1 - Budget Manager'!B5="","",'Step 1 - Budget Manager'!F5) | E8: =IF('Step 1 - Budget Manager'!B5="","",'Step 1 - Budget Manager'!G5) | F8: =IF('Step 1 - Budget Manager'!B5="","",IF('Step 1 - Budget Manager'!C5="","","Fund Code")) | G8: =IF('Step 1 - Budget Manager'!B5="","",IF('Step 1 - Budget Manager'!C5="","","Equals")) | H8: =IF('Step 1 - Budget Manager'!B5="","",IF('Step 1 - Budget Manager'!C5="","",'Step 1 - Budget Manager'!C5)) | I8: =IF('Step 1 - Budget Manager'!B5="","","Organization Code") | J8: =IF('Step 1 - Budget Manager'!B5="","","Equals") | K8: =IF('Step 1 - Budget Manager'!B5="","",'Step 1 - Budget Manager'!D5) | L8: =IF('Step 1 - Budget Manager'!B5="","","Other Criteria") | M8: =IF('Step 1 - Budget Manager'!B5="","","Equals") | N8: =IF('Step 1 - Budget Manager'!B5="","",'Step 1 - Budget Manager'!E5) | O8: ="" | P8: ="" | Q8: ="" | R8: ="" | S8: ="" | T8: ="" | U8: =IF('Step 1 - Budget Manager'!B5="","",'Step 1 - Budget Manager'!H5) | V8: =IF('Step 1 - Budget Manager'!B5="","",'Step 1 - Budget Manager'!J5) | W8: =IF('Step 1 - Budget Manager'!B5="","",'Step 1 - Budget Manager'!K5) | X8: =IF('Step 1 - Budget Manager'!B5="","",'Step 1 - Budget Manager'!M5) | Y8: =IF('Step 1 - Budget Manager'!B5="","",'Step 1 - Budget Manager'!N5) | Z8: ="" | AA8: ="" | AB8: ="" | AC8: ="" | AD8: ="" | AE8: ="" | AF8: ="" | AG8: ="" | ... AM8: =""
A9: =IF('Step 1 - Budget Manager'!B6="","","Active") | B9: =IF('Step 1 - Budget Manager'!B6="","",'Step 1 - Budget Manager'!B6) | C9: =IF('Step 1 - Budget Manager'!B6="","",'Step 1 - Budget Manager'!B6) | D9: =IF('Step 1 - Budget Manager'!B6="","",'Step 1 - Budget Manager'!F6) | E9: =IF('Step 1 - Budget Manager'!B6="","",'Step 1 - Budget Manager'!G6) | F9: =IF('Step 1 - Budget Manager'!B6="","",IF('Step 1 - Budget Manager'!C6="","","Fund Code")) | G9: =IF('Step 1 - Budget Manager'!B6="","",IF('Step 1 - Budget Manager'!C6="","","Equals")) | H9: =IF('Step 1 - Budget Manager'!B6="","",IF('Step 1 - Budget Manager'!C6="","",'Step 1 - Budget Manager'!C6)) | I9: =IF('Step 1 - Budget Manager'!B6="","","Organization Code") | J9: =IF('Step 1 - Budget Manager'!B6="","","Equals") | K9: =IF('Step 1 - Budget Manager'!B6="","",'Step 1 - Budget Manager'!D6) | L9: =IF('Step 1 - Budget Manager'!B6="","","Other Criteria") | M9: =IF('Step 1 - Budget Manager'!B6="","","Equals") | N9: =IF('Step 1 - Budget Manager'!B6="","",'Step 1 - Budget Manager'!E6) | O9: ="" | P9: ="" | Q9: ="" | R9: ="" | S9: ="" | T9: ="" | U9: =IF('Step 1 - Budget Manager'!B6="","",'Step 1 - Budget Manager'!H6) | V9: =IF('Step 1 - Budget Manager'!B6="","",'Step 1 - Budget Manager'!J6) | W9: =IF('Step 1 - Budget Manager'!B6="","",'Step 1 - Budget Manager'!K6) | X9: =IF('Step 1 - Budget Manager'!B6="","",'Step 1 - Budget Manager'!M6) | Y9: =IF('Step 1 - Budget Manager'!B6="","",'Step 1 - Budget Manager'!N6) | Z9: ="" | AA9: ="" | AB9: ="" | AC9: ="" | AD9: ="" | AE9: ="" | AF9: ="" | AG9: ="" | ... AM9: =""
A10: =IF('Step 1 - Budget Manager'!B7="","","Active") | B10: =IF('Step 1 - Budget Manager'!B7="","",'Step 1 - Budget Manager'!B7) | C10: =IF('Step 1 - Budget Manager'!B7="","",'Step 1 - Budget Manager'!B7) | D10: =IF('Step 1 - Budget Manager'!B7="","",'Step 1 - Budget Manager'!F7) | E10: =IF('Step 1 - Budget Manager'!B7="","",'Step 1 - Budget Manager'!G7) | F10: =IF('Step 1 - Budget Manager'!B7="","",IF('Step 1 - Budget Manager'!C7="","","Fund Code")) | G10: =IF('Step 1 - Budget Manager'!B7="","",IF('Step 1 - Budget Manager'!C7="","","Equals")) | H10: =IF('Step 1 - Budget Manager'!B7="","",IF('Step 1 - Budget Manager'!C7="","",'Step 1 - Budget Manager'!C7)) | I10: =IF('Step 1 - Budget Manager'!B7="","","Organization Code") | J10: =IF('Step 1 - Budget Manager'!B7="","","Equals") | K10: =IF('Step 1 - Budget Manager'!B7="","",'Step 1 - Budget Manager'!D7) | L10: =IF('Step 1 - Budget Manager'!B7="","","Other Criteria") | M10: =IF('Step 1 - Budget Manager'!B7="","","Equals") | N10: =IF('Step 1 - Budget Manager'!B7="","",'Step 1 - Budget Manager'!E7) | O10: ="" | P10: ="" | Q10: ="" | R10: ="" | S10: ="" | T10: ="" | U10: =IF('Step 1 - Budget Manager'!B7="","",'Step 1 - Budget Manager'!H7) | V10: =IF('Step 1 - Budget Manager'!B7="","",'Step 1 - Budget Manager'!J7) | W10: =IF('Step 1 - Budget Manager'!B7="","",'Step 1 - Budget Manager'!K7) | X10: =IF('Step 1 - Budget Manager'!B7="","",'Step 1 - Budget Manager'!M7) | Y10: =IF('Step 1 - Budget Manager'!B7="","",'Step 1 - Budget Manager'!N7) | Z10: ="" | AA10: ="" | AB10: ="" | AC10: ="" | AD10: ="" | AE10: ="" | AF10: ="" | AG10: ="" | ... AM10: =""
A11: =IF('Step 1 - Budget Manager'!B8="","","Active") | B11: =IF('Step 1 - Budget Manager'!B8="","",'Step 1 - Budget Manager'!B8) | C11: =IF('Step 1 - Budget Manager'!B8="","",'Step 1 - Budget Manager'!B8) | D11: =IF('Step 1 - Budget Manager'!B8="","",'Step 1 - Budget Manager'!F8) | E11: =IF('Step 1 - Budget Manager'!B8="","",'Step 1 - Budget Manager'!G8) | F11: =IF('Step 1 - Budget Manager'!B8="","",IF('Step 1 - Budget Manager'!C8="","","Fund Code")) | G11: =IF('Step 1 - Budget Manager'!B8="","",IF('Step 1 - Budget Manager'!C8="","","Equals")) | H11: =IF('Step 1 - Budget Manager'!B8="","",IF('Step 1 - Budget Manager'!C8="","",'Step 1 - Budget Manager'!C8)) | I11: =IF('Step 1 - Budget Manager'!B8="","","Organization Code") | J11: =IF('Step 1 - Budget Manager'!B8="","","Equals") | K11: =IF('Step 1 - Budget Manager'!B8="","",'Step 1 - Budget Manager'!D8) | L11: =IF('Step 1 - Budget Manager'!B8="","","Other Criteria") | M11: =IF('Step 1 - Budget Manager'!B8="","","Equals") | N11: =IF('Step 1 - Budget Manager'!B8="","",'Step 1 - Budget Manager'!E8) | O11: ="" | P11: ="" | Q11: ="" | R11: ="" | S11: ="" | T11: ="" | U11: =IF('Step 1 - Budget Manager'!B8="","",'Step 1 - Budget Manager'!H8) | V11: =IF('Step 1 - Budget Manager'!B8="","",'Step 1 - Budget Manager'!J8) | W11: =IF('Step 1 - Budget Manager'!B8="","",'Step 1 - Budget Manager'!K8) | X11: =IF('Step 1 - Budget Manager'!B8="","",'Step 1 - Budget Manager'!M8) | Y11: =IF('Step 1 - Budget Manager'!B8="","",'Step 1 - Budget Manager'!N8) | Z11: ="" | AA11: ="" | AB11: ="" | AC11: ="" | AD11: ="" | AE11: ="" | AF11: ="" | AG11: ="" | ... AM11: =""
A12: =IF('Step 1 - Budget Manager'!B9="","","Active") | B12: =IF('Step 1 - Budget Manager'!B9="","",'Step 1 - Budget Manager'!B9) | C12: =IF('Step 1 - Budget Manager'!B9="","",'Step 1 - Budget Manager'!B9) | D12: =IF('Step 1 - Budget Manager'!B9="","",'Step 1 - Budget Manager'!F9) | E12: =IF('Step 1 - Budget Manager'!B9="","",'Step 1 - Budget Manager'!G9) | F12: =IF('Step 1 - Budget Manager'!B9="","",IF('Step 1 - Budget Manager'!C9="","","Fund Code")) | G12: =IF('Step 1 - Budget Manager'!B9="","",IF('Step 1 - Budget Manager'!C9="","","Equals")) | H12: =IF('Step 1 - Budget Manager'!B9="","",IF('Step 1 - Budget Manager'!C9="","",'Step 1 - Budget Manager'!C9)) | I12: =IF('Step 1 - Budget Manager'!B9="","","Organization Code") | J12: =IF('Step 1 - Budget Manager'!B9="","","Equals") | K12: =IF('Step 1 - Budget Manager'!B9="","",'Step 1 - Budget Manager'!D9) | L12: =IF('Step 1 - Budget Manager'!B9="","","Other Criteria") | M12: =IF('Step 1 - Budget Manager'!B9="","","Equals") | N12: =IF('Step 1 - Budget Manager'!B9="","",'Step 1 - Budget Manager'!E9) | O12: ="" | P12: ="" | Q12: ="" | R12: ="" | S12: ="" | T12: ="" | U12: =IF('Step 1 - Budget Manager'!B9="","",'Step 1 - Budget Manager'!H9) | V12: =IF('Step 1 - Budget Manager'!B9="","",'Step 1 - Budget Manager'!J9) | W12: =IF('Step 1 - Budget Manager'!B9="","",'Step 1 - Budget Manager'!K9) | X12: =IF('Step 1 - Budget Manager'!B9="","",'Step 1 - Budget Manager'!M9) | Y12: =IF('Step 1 - Budget Manager'!B9="","",'Step 1 - Budget Manager'!N9) | Z12: ="" | AA12: ="" | AB12: ="" | AC12: ="" | AD12: ="" | AE12: ="" | AF12: ="" | AG12: ="" | ... AM12: =""
A13: =IF('Step 1 - Budget Manager'!B10="","","Active") | B13: =IF('Step 1 - Budget Manager'!B10="","",'Step 1 - Budget Manager'!B10) | C13: =IF('Step 1 - Budget Manager'!B10="","",'Step 1 - Budget Manager'!B10) | D13: =IF('Step 1 - Budget Manager'!B10="","",'Step 1 - Budget Manager'!F10) | E13: =IF('Step 1 - Budget Manager'!B10="","",'Step 1 - Budget Manager'!G10) | F13: =IF('Step 1 - Budget Manager'!B10="","",IF('Step 1 - Budget Manager'!C10="","","Fund Code")) | G13: =IF('Step 1 - Budget Manager'!B10="","",IF('Step 1 - Budget Manager'!C10="","","Equals")) | H13: =IF('Step 1 - Budget Manager'!B10="","",IF('Step 1 - Budget Manager'!C10="","",'Step 1 - Budget Manager'!C10)) | I13: =IF('Step 1 - Budget Manager'!B10="","","Organization Code") | J13: =IF('Step 1 - Budget Manager'!B10="","","Equals") | K13: =IF('Step 1 - Budget Manager'!B10="","",'Step 1 - Budget Manager'!D10) | L13: =IF('Step 1 - Budget Manager'!B10="","","Other Criteria") | M13: =IF('Step 1 - Budget Manager'!B10="","","Equals") | N13: =IF('Step 1 - Budget Manager'!B10="","",'Step 1 - Budget Manager'!E10) | O13: ="" | P13: ="" | Q13: ="" | R13: ="" | S13: ="" | T13: ="" | U13: =IF('Step 1 - Budget Manager'!B10="","",'Step 1 - Budget Manager'!H10) | V13: =IF('Step 1 - Budget Manager'!B10="","",'Step 1 - Budget Manager'!J10) | W13: =IF('Step 1 - Budget Manager'!B10="","",'Step 1 - Budget Manager'!K10) | X13: =IF('Step 1 - Budget Manager'!B10="","",'Step 1 - Budget Manager'!M10) | Y13: =IF('Step 1 - Budget Manager'!B10="","",'Step 1 - Budget Manager'!N10) | Z13: ="" | AA13: ="" | AB13: ="" | AC13: ="" | AD13: ="" | AE13: ="" | AF13: ="" | AG13: ="" | ... AM13: =""
A14: =IF('Step 1 - Budget Manager'!B11="","","Active") | B14: =IF('Step 1 - Budget Manager'!B11="","",'Step 1 - Budget Manager'!B11) | C14: =IF('Step 1 - Budget Manager'!B11="","",'Step 1 - Budget Manager'!B11) | D14: =IF('Step 1 - Budget Manager'!B11="","",'Step 1 - Budget Manager'!F11) | E14: =IF('Step 1 - Budget Manager'!B11="","",'Step 1 - Budget Manager'!G11) | F14: =IF('Step 1 - Budget Manager'!B11="","",IF('Step 1 - Budget Manager'!C11="","","Fund Code")) | G14: =IF('Step 1 - Budget Manager'!B11="","",IF('Step 1 - Budget Manager'!C11="","","Equals")) | H14: =IF('Step 1 - Budget Manager'!B11="","",IF('Step 1 - Budget Manager'!C11="","",'Step 1 - Budget Manager'!C11)) | I14: =IF('Step 1 - Budget Manager'!B11="","","Organization Code") | J14: =IF('Step 1 - Budget Manager'!B11="","","Equals") | K14: =IF('Step 1 - Budget Manager'!B11="","",'Step 1 - Budget Manager'!D11) | L14: =IF('Step 1 - Budget Manager'!B11="","","Other Criteria") | M14: =IF('Step 1 - Budget Manager'!B11="","","Equals") | N14: =IF('Step 1 - Budget Manager'!B11="","",'Step 1 - Budget Manager'!E11) | O14: ="" | P14: ="" | Q14: ="" | R14: ="" | S14: ="" | T14: ="" | U14: =IF('Step 1 - Budget Manager'!B11="","",'Step 1 - Budget Manager'!H11) | V14: =IF('Step 1 - Budget Manager'!B11="","",'Step 1 - Budget Manager'!J11) | W14: =IF('Step 1 - Budget Manager'!B11="","",'Step 1 - Budget Manager'!K11) | X14: =IF('Step 1 - Budget Manager'!B11="","",'Step 1 - Budget Manager'!M11) | Y14: =IF('Step 1 - Budget Manager'!B11="","",'Step 1 - Budget Manager'!N11) | Z14: ="" | AA14: ="" | AB14: ="" | AC14: ="" | AD14: ="" | AE14: ="" | AF14: ="" | AG14: ="" | ... AM14: =""
A15: =IF('Step 1 - Budget Manager'!B12="","","Active") | B15: =IF('Step 1 - Budget Manager'!B12="","",'Step 1 - Budget Manager'!B12) | C15: =IF('Step 1 - Budget Manager'!B12="","",'Step 1 - Budget Manager'!B12) | D15: =IF('Step 1 - Budget Manager'!B12="","",'Step 1 - Budget Manager'!F12) | E15: =IF('Step 1 - Budget Manager'!B12="","",'Step 1 - Budget Manager'!G12) | F15: =IF('Step 1 - Budget Manager'!B12="","",IF('Step 1 - Budget Manager'!C12="","","Fund Code")) | G15: =IF('Step 1 - Budget Manager'!B12="","",IF('Step 1 - Budget Manager'!C12="","","Equals")) | H15: =IF('Step 1 - Budget Manager'!B12="","",IF('Step 1 - Budget Manager'!C12="","",'Step 1 - Budget Manager'!C12)) | I15: =IF('Step 1 - Budget Manager'!B12="","","Organization Code") | J15: =IF('Step 1 - Budget Manager'!B12="","","Equals") | K15: =IF('Step 1 - Budget Manager'!B12="","",'Step 1 - Budget Manager'!D12) | L15: =IF('Step 1 - Budget Manager'!B12="","","Other Criteria") | M15: =IF('Step 1 - Budget Manager'!B12="","","Equals") | N15: =IF('Step 1 - Budget Manager'!B12="","",'Step 1 - Budget Manager'!E12) | O15: ="" | P15: ="" | Q15: ="" | R15: ="" | S15: ="" | T15: ="" | U15: =IF('Step 1 - Budget Manager'!B12="","",'Step 1 - Budget Manager'!H12) | V15: =IF('Step 1 - Budget Manager'!B12="","",'Step 1 - Budget Manager'!J12) | W15: =IF('Step 1 - Budget Manager'!B12="","",'Step 1 - Budget Manager'!K12) | X15: =IF('Step 1 - Budget Manager'!B12="","",'Step 1 - Budget Manager'!M12) | Y15: =IF('Step 1 - Budget Manager'!B12="","",'Step 1 - Budget Manager'!N12) | Z15: ="" | AA15: ="" | AB15: ="" | AC15: ="" | AD15: ="" | AE15: ="" | AF15: ="" | AG15: ="" | ... AM15: =""
A16: =IF('Step 1 - Budget Manager'!B13="","","Active") | B16: =IF('Step 1 - Budget Manager'!B13="","",'Step 1 - Budget Manager'!B13) | C16: =IF('Step 1 - Budget Manager'!B13="","",'Step 1 - Budget Manager'!B13) | D16: =IF('Step 1 - Budget Manager'!B13="","",'Step 1 - Budget Manager'!F13) | E16: =IF('Step 1 - Budget Manager'!B13="","",'Step 1 - Budget Manager'!G13) | F16: =IF('Step 1 - Budget Manager'!B13="","",IF('Step 1 - Budget Manager'!C13="","","Fund Code")) | G16: =IF('Step 1 - Budget Manager'!B13="","",IF('Step 1 - Budget Manager'!C13="","","Equals")) | H16: =IF('Step 1 - Budget Manager'!B13="","",IF('Step 1 - Budget Manager'!C13="","",'Step 1 - Budget Manager'!C13)) | I16: =IF('Step 1 - Budget Manager'!B13="","","Organization Code") | J16: =IF('Step 1 - Budget Manager'!B13="","","Equals") | K16: =IF('Step 1 - Budget Manager'!B13="","",'Step 1 - Budget Manager'!D13) | L16: =IF('Step 1 - Budget Manager'!B13="","","Other Criteria") | M16: =IF('Step 1 - Budget Manager'!B13="","","Equals") | N16: =IF('Step 1 - Budget Manager'!B13="","",'Step 1 - Budget Manager'!E13) | O16: ="" | P16: ="" | Q16: ="" | R16: ="" | S16: ="" | T16: ="" | U16: =IF('Step 1 - Budget Manager'!B13="","",'Step 1 - Budget Manager'!H13) | V16: =IF('Step 1 - Budget Manager'!B13="","",'Step 1 - Budget Manager'!J13) | W16: =IF('Step 1 - Budget Manager'!B13="","",'Step 1 - Budget Manager'!K13) | X16: =IF('Step 1 - Budget Manager'!B13="","",'Step 1 - Budget Manager'!M13) | Y16: =IF('Step 1 - Budget Manager'!B13="","",'Step 1 - Budget Manager'!N13) | Z16: ="" | AA16: ="" | AB16: ="" | AC16: ="" | AD16: ="" | AE16: ="" | AF16: ="" | AG16: ="" | ... AM16: =""
A17: =IF('Step 1 - Budget Manager'!B14="","","Active") | B17: =IF('Step 1 - Budget Manager'!B14="","",'Step 1 - Budget Manager'!B14) | C17: =IF('Step 1 - Budget Manager'!B14="","",'Step 1 - Budget Manager'!B14) | D17: =IF('Step 1 - Budget Manager'!B14="","",'Step 1 - Budget Manager'!F14) | E17: =IF('Step 1 - Budget Manager'!B14="","",'Step 1 - Budget Manager'!G14) | F17: =IF('Step 1 - Budget Manager'!B14="","",IF('Step 1 - Budget Manager'!C14="","","Fund Code")) | G17: =IF('Step 1 - Budget Manager'!B14="","",IF('Step 1 - Budget Manager'!C14="","","Equals")) | H17: =IF('Step 1 - Budget Manager'!B14="","",IF('Step 1 - Budget Manager'!C14="","",'Step 1 - Budget Manager'!C14)) | I17: =IF('Step 1 - Budget Manager'!B14="","","Organization Code") | J17: =IF('Step 1 - Budget Manager'!B14="","","Equals") | K17: =IF('Step 1 - Budget Manager'!B14="","",'Step 1 - Budget Manager'!D14) | L17: =IF('Step 1 - Budget Manager'!B14="","","Other Criteria") | M17: =IF('Step 1 - Budget Manager'!B14="","","Equals") | N17: =IF('Step 1 - Budget Manager'!B14="","",'Step 1 - Budget Manager'!E14) | O17: ="" | P17: ="" | Q17: ="" | R17: ="" | S17: ="" | T17: ="" | U17: =IF('Step 1 - Budget Manager'!B14="","",'Step 1 - Budget Manager'!H14) | V17: =IF('Step 1 - Budget Manager'!B14="","",'Step 1 - Budget Manager'!J14) | W17: =IF('Step 1 - Budget Manager'!B14="","",'Step 1 - Budget Manager'!K14) | X17: =IF('Step 1 - Budget Manager'!B14="","",'Step 1 - Budget Manager'!M14) | Y17: =IF('Step 1 - Budget Manager'!B14="","",'Step 1 - Budget Manager'!N14) | Z17: ="" | AA17: ="" | AB17: ="" | AC17: ="" | AD17: ="" | AE17: ="" | AF17: ="" | AG17: ="" | ... AM17: =""
A18: =IF('Step 1 - Budget Manager'!B15="","","Active") | B18: =IF('Step 1 - Budget Manager'!B15="","",'Step 1 - Budget Manager'!B15) | C18: =IF('Step 1 - Budget Manager'!B15="","",'Step 1 - Budget Manager'!B15) | D18: =IF('Step 1 - Budget Manager'!B15="","",'Step 1 - Budget Manager'!F15) | E18: =IF('Step 1 - Budget Manager'!B15="","",'Step 1 - Budget Manager'!G15) | F18: =IF('Step 1 - Budget Manager'!B15="","",IF('Step 1 - Budget Manager'!C15="","","Fund Code")) | G18: =IF('Step 1 - Budget Manager'!B15="","",IF('Step 1 - Budget Manager'!C15="","","Equals")) | H18: =IF('Step 1 - Budget Manager'!B15="","",IF('Step 1 - Budget Manager'!C15="","",'Step 1 - Budget Manager'!C15)) | I18: =IF('Step 1 - Budget Manager'!B15="","","Organization Code") | J18: =IF('Step 1 - Budget Manager'!B15="","","Equals") | K18: =IF('Step 1 - Budget Manager'!B15="","",'Step 1 - Budget Manager'!D15) | L18: =IF('Step 1 - Budget Manager'!B15="","","Other Criteria") | M18: =IF('Step 1 - Budget Manager'!B15="","","Equals") | N18: =IF('Step 1 - Budget Manager'!B15="","",'Step 1 - Budget Manager'!E15) | O18: ="" | P18: ="" | Q18: ="" | R18: ="" | S18: ="" | T18: ="" | U18: =IF('Step 1 - Budget Manager'!B15="","",'Step 1 - Budget Manager'!H15) | V18: =IF('Step 1 - Budget Manager'!B15="","",'Step 1 - Budget Manager'!J15) | W18: =IF('Step 1 - Budget Manager'!B15="","",'Step 1 - Budget Manager'!K15) | X18: =IF('Step 1 - Budget Manager'!B15="","",'Step 1 - Budget Manager'!M15) | Y18: =IF('Step 1 - Budget Manager'!B15="","",'Step 1 - Budget Manager'!N15) | Z18: ="" | AA18: ="" | AB18: ="" | AC18: ="" | AD18: ="" | AE18: ="" | AF18: ="" | AG18: ="" | ... AM18: =""
A19: =IF('Step 1 - Budget Manager'!B16="","","Active") | B19: =IF('Step 1 - Budget Manager'!B16="","",'Step 1 - Budget Manager'!B16) | C19: =IF('Step 1 - Budget Manager'!B16="","",'Step 1 - Budget Manager'!B16) | D19: =IF('Step 1 - Budget Manager'!B16="","",'Step 1 - Budget Manager'!F16) | E19: =IF('Step 1 - Budget Manager'!B16="","",'Step 1 - Budget Manager'!G16) | F19: =IF('Step 1 - Budget Manager'!B16="","",IF('Step 1 - Budget Manager'!C16="","","Fund Code")) | G19: =IF('Step 1 - Budget Manager'!B16="","",IF('Step 1 - Budget Manager'!C16="","","Equals")) | H19: =IF('Step 1 - Budget Manager'!B16="","",IF('Step 1 - Budget Manager'!C16="","",'Step 1 - Budget Manager'!C16)) | I19: =IF('Step 1 - Budget Manager'!B16="","","Organization Code") | J19: =IF('Step 1 - Budget Manager'!B16="","","Equals") | K19: =IF('Step 1 - Budget Manager'!B16="","",'Step 1 - Budget Manager'!D16) | L19: =IF('Step 1 - Budget Manager'!B16="","","Other Criteria") | M19: =IF('Step 1 - Budget Manager'!B16="","","Equals") | N19: =IF('Step 1 - Budget Manager'!B16="","",'Step 1 - Budget Manager'!E16) | O19: ="" | P19: ="" | Q19: ="" | R19: ="" | S19: ="" | T19: ="" | U19: =IF('Step 1 - Budget Manager'!B16="","",'Step 1 - Budget Manager'!H16) | V19: =IF('Step 1 - Budget Manager'!B16="","",'Step 1 - Budget Manager'!J16) | W19: =IF('Step 1 - Budget Manager'!B16="","",'Step 1 - Budget Manager'!K16) | X19: =IF('Step 1 - Budget Manager'!B16="","",'Step 1 - Budget Manager'!M16) | Y19: =IF('Step 1 - Budget Manager'!B16="","",'Step 1 - Budget Manager'!N16) | Z19: ="" | AA19: ="" | AB19: ="" | AC19: ="" | AD19: ="" | AE19: ="" | AF19: ="" | AG19: ="" | ... AM19: =""
... A56: =IF('Step 1 - Budget Manager'!B53="","","Active") | B56: =IF('Step 1 - Budget Manager'!B53="","",'Step 1 - Budget Manager'!B53) | C56: =IF('Step 1 - Budget Manager'!B53="","",'Step 1 - Budget Manager'!B53) | D56: =IF('Step 1 - Budget Manager'!B53="","",'Step 1 - Budget Manager'!F53) | E56: =IF('Step 1 - Budget Manager'!B53="","",'Step 1 - Budget Manager'!G53) | F56: =IF('Step 1 - Budget Manager'!B53="","",IF('Step 1 - Budget Manager'!C53="","","Fund Code")) | G56: =IF('Step 1 - Budget Manager'!B53="","",IF('Step 1 - Budget Manager'!C53="","","Equals")) | H56: =IF('Step 1 - Budget Manager'!B53="","",IF('Step 1 - Budget Manager'!C53="","",'Step 1 - Budget Manager'!C53)) | I56: =IF('Step 1 - Budget Manager'!B53="","","Organization Code") | J56: =IF('Step 1 - Budget Manager'!B53="","","Equals") | K56: =IF('Step 1 - Budget Manager'!B53="","",'Step 1 - Budget Manager'!D53) | L56: =IF('Step 1 - Budget Manager'!B53="","","Other Criteria") | M56: =IF('Step 1 - Budget Manager'!B53="","","Equals") | N56: =IF('Step 1 - Budget Manager'!B53="","",'Step 1 - Budget Manager'!E53) | O56: ="" | P56: ="" | Q56: ="" | R56: ="" | S56: ="" | T56: ="" | U56: =IF('Step 1 - Budget Manager'!B53="","",'Step 1 - Budget Manager'!H53) | V56: =IF('Step 1 - Budget Manager'!B53="","",'Step 1 - Budget Manager'!J53) | W56: =IF('Step 1 - Budget Manager'!B53="","",'Step 1 - Budget Manager'!K53) | X56: =IF('Step 1 - Budget Manager'!B53="","",'Step 1 - Budget Manager'!M53) | Y56: =IF('Step 1 - Budget Manager'!B53="","",'Step 1 - Budget Manager'!N53) | Z56: ="" | AA56: ="" | AB56: ="" | AC56: ="" | AD56: ="" | AE56: ="" | AF56: ="" | AG56: ="" | ... AM56: =""
A57: v Step 2 - Special Approvals (from 'Step 2 - Special' tab) v
A58: =IF('Step 2 - Special'!B5="","","Active") | B58: =IF('Step 2 - Special'!B5="","",'Step 2 - Special'!B5) | C58: =IF('Step 2 - Special'!B5="","",'Step 2 - Special'!B5) | D58: =IF('Step 2 - Special'!B5="","",'Step 2 - Special'!F5) | E58: =IF('Step 2 - Special'!B5="","",'Step 2 - Special'!G5) | F58: =IF('Step 2 - Special'!B5="","",IF('Step 2 - Special'!C5="","","Fund Code")) | G58: =IF('Step 2 - Special'!B5="","",IF('Step 2 - Special'!C5="","","Equals")) | H58: =IF('Step 2 - Special'!B5="","",IF('Step 2 - Special'!C5="","",'Step 2 - Special'!C5)) | I58: =IF('Step 2 - Special'!B5="","","Organization Code") | J58: =IF('Step 2 - Special'!B5="","","Equals") | K58: =IF('Step 2 - Special'!B5="","",'Step 2 - Special'!D5) | L58: =IF('Step 2 - Special'!B5="","","Other Criteria") | M58: =IF('Step 2 - Special'!B5="","","Equals") | N58: =IF('Step 2 - Special'!B5="","",'Step 2 - Special'!E5) | O58: ="" | P58: ="" | Q58: ="" | R58: ="" | S58: ="" | T58: ="" | U58: =IF('Step 2 - Special'!B5="","",'Step 2 - Special'!H5) | V58: =IF('Step 2 - Special'!B5="","",'Step 2 - Special'!J5) | W58: =IF('Step 2 - Special'!B5="","",'Step 2 - Special'!K5) | X58: =IF('Step 2 - Special'!B5="","",'Step 2 - Special'!M5) | Y58: ="" | Z58: ="" | AA58: ="" | AB58: ="" | AC58: ="" | AD58: ="" | AE58: ="" | AF58: ="" | ... AM58: =""
A59: =IF('Step 2 - Special'!B6="","","Active") | B59: =IF('Step 2 - Special'!B6="","",'Step 2 - Special'!B6) | C59: =IF('Step 2 - Special'!B6="","",'Step 2 - Special'!B6) | D59: =IF('Step 2 - Special'!B6="","",'Step 2 - Special'!F6) | E59: =IF('Step 2 - Special'!B6="","",'Step 2 - Special'!G6) | F59: =IF('Step 2 - Special'!B6="","",IF('Step 2 - Special'!C6="","","Fund Code")) | G59: =IF('Step 2 - Special'!B6="","",IF('Step 2 - Special'!C6="","","Equals")) | H59: =IF('Step 2 - Special'!B6="","",IF('Step 2 - Special'!C6="","",'Step 2 - Special'!C6)) | I59: =IF('Step 2 - Special'!B6="","","Organization Code") | J59: =IF('Step 2 - Special'!B6="","","Equals") | K59: =IF('Step 2 - Special'!B6="","",'Step 2 - Special'!D6) | L59: =IF('Step 2 - Special'!B6="","","Other Criteria") | M59: =IF('Step 2 - Special'!B6="","","Equals") | N59: =IF('Step 2 - Special'!B6="","",'Step 2 - Special'!E6) | O59: ="" | P59: ="" | Q59: ="" | R59: ="" | S59: ="" | T59: ="" | U59: =IF('Step 2 - Special'!B6="","",'Step 2 - Special'!H6) | V59: =IF('Step 2 - Special'!B6="","",'Step 2 - Special'!J6) | W59: =IF('Step 2 - Special'!B6="","",'Step 2 - Special'!K6) | X59: =IF('Step 2 - Special'!B6="","",'Step 2 - Special'!M6) | Y59: ="" | Z59: ="" | AA59: ="" | AB59: ="" | AC59: ="" | AD59: ="" | AE59: ="" | AF59: ="" | ... AM59: =""
